Workbook

Sheet Lançamentos
A1: Data | B1: Codigo | C1: Fuso Retificado | D1: Fuso Retificado Adaptado | E1: Castanha Retificada Adaptada | F1: Fuso Laminado | G1: Castanha Laminada Adaptada | H1: Fuso Laminado Adaptado | I1: Guia | J1: Bloco | K1: Cliente | L1: Pedido | M1: OP | N1: Peças produzidas | O1: Aprovado | P1: Reprovado | Q1: Usinagem | R1: Inspeção | S1: Desenho | T1: Programação CNC | U1: Produção | V1: Comercial | W1: PCP | X1: RETRABALHO OUTROS DP | Y1: Retrabalho | Z1: Morta outros | AA1: Morta usin. | AB1: Data de entrada | AC1: Data de saída | AD1: Inspetor | AE1: Inspetor Responsavél | AF1: Observação
A2: LOGO | K2: CONTROLE DE QUALIDADE | AG2: DASH!A1
A3: Data | B3: Codigo | C3: Fuso Retificado | D3: Fuso Retificado Adaptado | E3: Castanha Retificada Adaptada | F3: Fuso Laminado | G3: Fuso Laminado Adaptado | H3: Castanha Laminada Adaptada | I3: Guia | J3: Bloco | K3: Cliente | L3: Pedido | M3: OP | N3: Peças produzidas | O3: Aprovado | P3: Reprovado | Q3: Usinagem | R3: Inspeção | S3: Desenho | T3: Programação CNC | U3: Produção | V3: Comercial | W3: PCP | X3: RETRABALHO OUTROS DP | Y3: Retrabalho | Z3: Morta outros | AA3: Morta usin. | AB3: Data de entrada | AC3: Data de saída | AD3: Inspetor | AE3: Inspetor Responsavél | AF3: Observação
A4: 45597 | B4: 046899 | C4: 2 | D4: 0 | E4: 0 | F4: 0 | G4: 0 | H4: 0 | I4: 0 | J4: 0 | K4: MAHLE | L4: 0084540 | M4: 0370801001 | N4: 2 | O4: 1 | P4: 1 | Q4: 1 | R4: 0 | S4: 0 | T4: 0 | U4: 0 | V4: 0 | W4: 0 | X4: 0 | Y4: 1 | Z4: 0 | AA4: 0 | AB4: 45597 | AC4: 45597 | AD4: JOSE/ALEXANDRE | AE4: WILLIAN | AF4: PORCA CALIBRADORA NÃO ESTAVA PASSANDO NA ROSCA M40x1.5 DIMENSIONAL ALEXANDRE
A5: 04/11/2024 | B5: 052104 | C5: 0 | D5: 0 | E5: 0 | F5: 1 | G5: 0 | H5: 0 | I5: 0 | J5: 0 | K5: TOX | L5: 0084655 | M5: 03757801001 | N5: 1 | O5: 1 | P5: 0 | Q5: 0 | R5: 0 | S5: 0 | T5: 0 | U5: 0 | V5: 0 | W5: 0 | X5: 0 | Y5: 0 | Z5: 0 | AA5: 0 | AB5: 04/11/2024 | AC5: 04/11/2024 | AD5: JOSE/WILLIAN | AE5: WILLIAN | AF5: DIMENSIONAL JOSE / DESEMPENO E MONTAGEM DE CASTANHA WILLIAN
A6: 04/11/2024 | B6: 006968 | C6: 0 | D6: 0 | E6: 0 | F6: 1 | G6: 0 | H6: 0 | I6: 0 | J6: 0 | K6: RAUMAK | L6: 0084597 | M6: 03757001001 | N6: 1 | O6: 1 | P6: 0 | Q6: 0 | R6: 0 | S6: 0 | T6: 0 | U6: 0 | V6: 0 | W6: 0 | X6: 0 | Y6: 0 | Z6: 0 | AA6: 0 | AB6: 04/11/2024 | AC6: 04/11/2024 | AD6: JOSE | AE6: WILLIAN
A7: 04/11/2024 | B7: 051664 | C7: 0 | D7: 0 | E7: 0 | F7: 8 | G7: 0 | H7: 0 | I7: 0 | J7: 0 | K7: FLEXOPOWER | L7: 0083870 | M7: 03749901010 | N7: 8 | O7: 8 | P7: 0 | Q7: 0 | R7: 0 | S7: 0 | T7: 0 | U7: 0 | V7: 0 | W7: 0 | X7: 0 | Y7: 0 | Z7: 0 | AA7: 0 | AB7: 04/11/2024 | AC7: 04/11/2024 | AD7: ALEXANDRE | AE7: WILLIAN | AF7: DIMENSIONAL ALEXANDRE DESEMPENO CONFERIDO POR WILLIAN
A8: 04/11/2024 | B8: 051665 | C8: 0 | D8: 0 | E8: 0 | F8: 4 | G8: 0 | H8: 0 | I8: 0 | J8: 0 | K8: FLEXOPOWER | L8: 0083870 | M8: 03749901011 | N8: 4 | O8: 4 | P8: 0 | Q8: 0 | R8: 0 | S8: 0 | T8: 0 | U8: 0 | V8: 0 | W8: 0 | X8: 0 | Y8: 0 | Z8: 0 | AA8: 0 | AB8: 04/11/2024 | AC8: 04/11/2024 | AD8: ALEXANDRE | AE8: WILLIAN | AF8: DIMENSIONAL ALEXANDRE DESEMPENO CONFERIDO POR JOSÉ
A9: 04/11/2024 | B9: 040639 | C9: 0 | D9: 0 | E9: 0 | F9: 1 | G9: 0 | H9: 0 | I9: 0 | J9: 0 | K9: AUTOLIV | L9: 0084704 | M9: 03760801001 | N9: 1 | O9: 1 | P9: 0 | Q9: 0 | R9: 0 | S9: 0 | T9: 0 | U9: 0 | V9: 0 | W9: 0 | X9: 0 | Y9: 0 | Z9: 0 | AA9: 0 | AB9: 04/11/2024 | AC9: 04/11/2024 | AD9: WILLIAN | AE9: WILLIAN
A10: 05/11/2024 | B10: 050797 | C10: 0 | D10: 0 | E10: 0 | F10: 0 | G10: 0 | H10: 0 | I10: 2 | J10: 0 | K10: MOTOMAN | L10: 0082620 | M10: 03728701004 | N10: 2 | O10: 2 | P10: 0 | Q10: 0 | R10: 0 | S10: 0 | T10: 0 | U10: 0 | V10: 0 | W10: 0 | X10: 0 | Y10: 0 | Z10: 0 | AA10: 0 | AB10: 05/11/2024 | AC10: 05/11/2024 | AD10: JOSÉ | AE10: WILLIAN | AF10: GUIA COM 5 DÉCIMOS MENOR EM CADA CORPO COM COMPRIMENTO DE 3412.5mm E 1417.5mm TOTALIZANDO 2 MILIMETROS MENNOR NA EMENDA COMPLETA. FOI LIBEARADA DESTA FORMA
A11: 05/11/2024 | B11: 052097 | C11: 0 | D11: 0 | E11: 0 | F11: 2 | G11: 0 | H11: 0 | I11: 0 | J11: 0 | K11: COMERCIAL | L11: 0084598 | M11: 03754601001 | N11: 2 | O11: 2 | P11: 0 | Q11: 0 | R11: 0 | S11: 0 | T11: 0 | U11: 0 | V11: 0 | W11: 0 | X11: 0 | Y11: 0 | Z11: 0 | AA11: 0 | AB11: 05/11/2024 | AC11: 05/11/2024 | AD11: JOSÉ | AE11: WILLIAN
A12: 05/11/2024 | B12: 051603 | C12: 0 | D12: 0 | E12: 0 | F12: 2 | G12: 0 | H12: 0 | I12: 0 | J12: 0 | K12: MULTIPACK | L12: 0083822 | M12: 03693901001 | N12: 2 | O12: 2 | P12: 0 | Q12: 0 | R12: 0 | S12: 0 | T12: 0 | U12: 0 | V12: 0 | W12: 0 | X12: 0 | Y12: 0 | Z12: 0 | AA12: 0 | AB12: 05/11/2024 | AC12: 05/11/2024 | AD12: JOSÉ | AE12: WILLIAN
A13: 05/11/2024 | B13: 052020 | C13: 0 | D13: 0 | E13: 0 | F13: 0 | G13: 0 | H13: 0 | I13: 2 | J13: 0 | K13: COMAC | L13: 0084636 | M13: 03757301001 | N13: 2 | O13: 2 | P13: 0 | Q13: 0 | R13: 0 | S13: 0 | T13: 0 | U13: 0 | V13: 0 | W13: 0 | X13: 0 | Y13: 0 | Z13: 0 | AA13: 0 | AB13: 05/11/2024 | AC13: 05/11/2024 | AD13: JOSÉ | AE13: WILLIAN | AF13: COVER CONFERIDO POR ALEXANDRE
A14: 05/11/2024 | B14: 052136 | C14: 0 | D14: 1 | E14: 1 | F14: 0 | G14: 0 | H14: 0 | I14: 0 | J14: 0 | K14: MGFC | L14: #28959 | M14: 03750601001 | N14: 1 | O14: 1 | P14: 0 | Q14: 0 | R14: 0 | S14: 0 | T14: 0 | U14: 0 | V14: 0 | W14: 0 | X14: 0 | Y14: 0 | Z14: 0 | AA14: 0 | AB14: 05/11/2024 | AC14: 05/11/2024 | AD14: JOSÉ | AE14: WILLIAN | AF14: DESEMPENO WILLIAN
A15: 05/11/2024 | B15: 052114 | C15: 0 | D15: 0 | E15: 0 | F15: 0 | G15: 2 | H15: 0 | I15: 0 | J15: 0 | K15: MACCAFERRI | L15: 0084544 | M15: 03751801001 | N15: 2 | O15: 1 | P15: 1 | Q15: 1 | R15: 0 | S15: 0 | T15: 0 | U15: 0 | V15: 0 | W15: 0 | X15: 0 | Y15: 1 | Z15: 0 | AA15: 0 | AB15: 05/11/2024 | AC15: 05/11/2024 | AD15: JOSÉ | AE15: WILLIAN | AF15: FLANGE MAIOR 25.6MM E PRECISO MENOR 4.4MM - OCOREU COMPENSAÇÃO DE MEDIDAS
A16: 05/11/2024 | B16: 052163 | C16: 0 | D16: 0 | E16: 0 | F16: 2 | G16: 0 | H16: 0 | I16: 0 | J16: 0 | K16: CERUMAQ | L16: 0084648 | M16: 03760201001 | N16: 2 | O16: 2 | P16: 0 | Q16: 0 | R16: 0 | S16: 0 | T16: 0 | U16: 0 | V16: 0 | W16: 0 | X16: 0 | Y16: 0 | Z16: 0 | AA16: 0 | AB16: 05/11/2024 | AC16: 05/11/2024 | AD16: JOSÉ | AE16: WILLIAN | AF16: DIMENSIONAL ALEXANDRE
A17: 06/11/2024 | B17: 052103 | C17: 0 | D17: 0 | E17: 0 | F17: 1 | G17: 0 | H17: 0 | I17: 0 | J17: 0 | K17: CONAN | L17: 0084680 | M17: 03761801009 | N17: 1 | O17: 1 | P17: 0 | Q17: 0 | R17: 0 | S17: 0 | T17: 0 | U17: 0 | V17: 0 | W17: 0 | X17: 0 | Y17: 0 | Z17: 0 | AA17: 0 | AB17: 06/11/2024 | AC17: 06/11/2024 | AD17: JOSÉ | AE17: WILLIAN | AF17: NO CORPO DE 11mm DE COMPRIMENTO A MEDIDA DO DIAMETRO DE 10mm ESTÁ COM 10mm -0.1 POR QUE ERA PARA SEEGUIR O DESENHO ANTIGO E NÃO O NOVO QUE ESTA SEM A TOLERANCIA DO PEDAÇO QUE VAI O CHANFRO FINAL DA PEÇA.PEÇA FOI LIBERADA COM ESSA MEDIDA PELO DESENHO ANTIGO
A18: 06/11/2024 | B18: 045673 | C18: 1 | D18: 0 | E18: 0 | F18: 0 | G18: 0 | H18: 0 | I18: 0 | J18: 0 | K18: ALTONA | L18: ESTOQUE | M18: 03573801001 | N18: 1 | O18: 1 | P18: 0 | Q18: 0 | R18: 0 | S18: 0 | T18: 0 | U18: 0 | V18: 0 | W18: 0 | X18: 0 | Y18: 0 | Z18: 0 | AA18: 0 | AB18: 06/11/2024 | AC18: 06/11/2024 | AD18: WILLIAN | AE18: WILLIAN
A19: 06/11/2024 | B19: 050919 | C19: 0 | D19: 0 | E19: 0 | F19: 0 | G19: 5 | H19: 0 | I19: 0 | J19: 0 | K19: PX | L19: 0084349 | M19: 03751901001 | N19: 5 | O19: 5 | P19: 0 | Q19: 0 | R19: 0 | S19: 0 | T19: 0 | U19: 0 | V19: 0 | W19: 0 | X19: 0 | Y19: 0 | Z19: 0 | AA19: 0 | AB19: 06/11/2024 | AC19: 06/11/2024 | AD19: JOSÉ | AE19: WILLIAN
A20: 06/11/2024 | B20: 052102 | C20: 0 | D20: 0 | E20: 0 | F20: 1 | G20: 0 | H20: 0 | I20: 0 | J20: 0 | K20: CONAN | L20: 0084680 | M20: 03761801008 | N20: 1 | O20: 0 | P20: 1 | Q20: 1 | R20: 0 | S20: 0 | T20: 0 | U20: 0 | V20: 0 | W20: 0 | X20: 0 | Y20: 1 | Z20: 0 | AA20: 0 | AB20: 06/11/2024 | AC20: 06/11/2024 | AD20: JOSÉ | AE20: WILLIAN | AF20: FUSO MORREU O CORPO DA FRENTE DE COMPRIMENTO 15mm DIAMETRO 10mm H7 E O CORPO DE 26mm DE COMPRIMENTO DIAMETRO DE 12mm h7 ESTAVA COM 50% FORA DE TOLERÂNCIA PEÇA OI LIBERADA POSSUI RNC E EMAIL.
A21: 06/11/2024 | B21: 037490 | C21: 0 | D21: 0 | E21: 0 | F21: 0 | G21: 0 | H21: 0 | I21: 2 | J21: 0 | K21: SILBER | L21: 0084468 | M21: 03746301003 | N21: 2 | O21: 2 | P21: 0 | Q21: 0 | R21: 0 | S21: 0 | T21: 0 | U21: 0 | V21: 0 | W21: 0 | X21: 0 | Y21: 0 | Z21: 0 | AA21: 0 | AB21: 06/11/2024 | AC21: 06/11/2024 | AD21: JOSÉ | AE21: WILLIAN | AF21: GUIA SÓ FACETADA PARA EMENDA FOI GRAVADA.
A22: 06/11/2024 | B22: 052125 | C22: 0 | D22: 0 | E22: 0 | F22: 0 | G22: 0 | H22: 0 | I22: 2 | J22: 0 | K22: SILBER | L22: 0084468 | M22: 03746301004 | N22: 2 | O22: 2 | P22: 0 | Q22: 0 | R22: 0 | S22: 0 | T22: 0 | U22: 0 | V22: 0 | W22: 0 | X22: 0 | Y22: 0 | Z22: 0 | AA22: 0 | AB22: 06/11/2024 | AC22: 06/11/2024 | AD22: JOSÉ | AE22: WILLIAN
A23: 06/11/2024 | B23: 052186 | C23: 1 | D23: 0 | E23: 0 | F23: 0 | G23: 0 | H23: 0 | I23: 0 | J23: 0 | K23: ZEN | L23: 0084681 | M23: 03760401001 | N23: 1 | O23: 1 | P23: 0 | Q23: 0 | R23: 0 | S23: 0 | T23: 0 | U23: 0 | V23: 0 | W23: 0 | X23: 0 | Y23: 0 | Z23: 0 | AA23: 0 | AC23: 06/11/2024 | AD23: JOSE/ALEXANDRE | AE23: WILLIAN
A24: 06/11/2024 | B24: 051881 | C24: 0 | D24: 0 | E24: 0 | F24: 0 | G24: 0 | H24: 0 | I24: 3 | J24: 0 | K24: MACLINEA | L24: 0084590 | M24: 03753501001 | N24: 3 | O24: 2 | P24: 1 | Q24: 0 | R24: 0 | S24: 0 | T24: 0 | U24: 1 | V24: 0 | W24: 0 | X24: 0 | Y24: 0 | Z24: 1 | AA24: 0 | AB24: 06/11/2024 | AC24: 06/11/2024 | AD24: WILLIAN | AE24: WILLIAN | AF24: GUIA MORREU NA HORA DO CORTE
A25: 07/11/2024 | B25: 052152 | C25: 0 | D25: 0 | E25: 0 | F25: 1 | G25: 0 | H25: 0 | I25: 0 | J25: 0 | K25: 2D SISTEMA | L25: 0084671 | M25: 03759401003 | N25: 1 | O25: 1 | P25: 0 | Q25: 0 | R25: 0 | S25: 0 | T25: 0 | U25: 0 | V25: 0 | W25: 0 | X25: 0 | Y25: 0 | Z25: 0 | AA25: 0 | AB25: 06/11/2024 | AC25: 06/11/2024 | AD25: JOSE | AE25: WILLIAN
A26: 07/11/2024 | B26: 052153 | C26: 0 | D26: 0 | E26: 0 | F26: 1 | G26: 0 | H26: 0 | I26: 0 | J26: 0 | K26: 2D SISTEMA | L26: 0084671 | M26: 03759401004 | N26: 1 | O26: 1 | P26: 0 | Q26: 0 | R26: 0 | S26: 0 | T26: 0 | U26: 0 | V26: 0 | W26: 0 | X26: 0 | Y26: 0 | Z26: 0 | AA26: 0 | AB26: 06/11/2024 | AC26: 06/11/2024 | AD26: JOSE/ALEXANDRE | AE26: WILLIAN
A27: 07/11/2024 | B27: 050922 | C27: 1 | D27: 0 | E27: 1 | F27: 0 | G27: 0 | H27: 0 | I27: 0 | J27: 0 | K27: NEUMAYER | L27: 0081637 | M27: 03747601001 | N27: 1 | O27: 0 | P27: 1 | Q27: 1 | R27: 0 | S27: 0 | T27: 0 | U27: 0 | V27: 0 | W27: 0 | X27: 0 | Y27: 1 | Z27: 0 | AA27: 0 | AB27: 07/11/2024 | AC27: 07/11/2024 | AD27: WILLIAN/ALEXANDRE | AE27: WILLIAN | AF27: AO REALIZAR A FURAÇÃO DO PARAFUSO DO RECIRCULADOR, O OPERADOR NÃO SE ATENTOU E PASSOU COM A FRESA ATE O FUSO
A28: 08/11/2024 | B28: 050763 | C28: 0 | D28: 0 | E28: 0 | F28: 3 | G28: 0 | H28: 0 | I28: 0 | J28: 0 | K28: OVERDRILL | L28: 0084577 | M28: 03755201002 | N28: 3 | O28: 3 | P28: 0 | Q28: 0 | R28: 0 | S28: 0 | T28: 0 | U28: 0 | V28: 0 | W28: 0 | X28: 0 | Y28: 0 | Z28: 0 | AA28: 0 | AB28: 08/11/2024 | AC28: 08/11/2024 | AD28: JOSÉ | AE28: WILLIAN
A29: 08/11/2024 | B29: 049469 | C29: 0 | D29: 0 | E29: 0 | F29: 6 | G29: 0 | H29: 0 | I29: 0 | J29: 0 | K29: OVERDRILL | L29: 0084577 | M29: 03755201001 | N29: 6 | O29: 6 | P29: 0 | Q29: 0 | R29: 0 | S29: 0 | T29: 0 | U29: 0 | V29: 0 | W29: 0 | X29: 0 | Y29: 0 | Z29: 0 | AA29: 0 | AB29: 08/11/2024 | AC29: 08/11/2024 | AD29: JOSÉ | AE29: WILLIAN | AF29: DIMENCIONAL ALEXANDRE / INSPEÇÃO JOSE / ENTREGA PARCIAL FUSO 1 E 6
A30: 08/11/2024 | B30: 051873 | C30: 1 | D30: 0 | E30: 0 | F30: 0 | G30: 0 | H30: 0 | I30: 0 | J30: 0 | K30: ALZILAN | L30: BP#31868 | M30: - | N30: 1 | O30: 0 | P30: 1 | Q30: 1 | R30: 0 | S30: 0 | T30: 0 | U30: 0 | V30: 0 | W30: 0 | X30: 0 | Y30: 1 | Z30: 0 | AA30: 0 | AB30: 08/11/2024 | AC30: 08/11/2024 | AD30: JOSÉ | AE30: WILLIAN | AF30: DIAMETRO DE 24,5mm H7(0/-0,021), FICOU UMA REGIAO DE 5mm DE COMPRIMENTO COM -0,05/-0,06.
A31: 08/11/2024 | B31: 037267 | C31: 0 | D31: 0 | E31: 0 | F31: 2 | G31: 0 | H31: 0 | I31: 0 | J31: 0 | K31: S V G | L31: 0068870 | M31: 03687901003 | N31: 2 | O31: 2 | P31: 0 | Q31: 0 | R31: 0 | S31: 0 | T31: 0 | U31: 0 | V31: 0 | W31: 0 | X31: 0 | Y31: 0 | Z31: 0 | AA31: 0 | AB31: 08/11/2024 | AC31: 08/11/2024 | AD31: JOSÉ | AE31: WILLIAN
A32: 08/11/2024 | B32: 052196 | C32: 0 | D32: 0 | E32: 0 | F32: 1 | G32: 0 | H32: 1 | I32: 0 | J32: 0 | K32: MAHLE | L32: 0084716 | M32: 03763101001 | N32: 1 | O32: 1 | P32: 0 | Q32: 0 | R32: 0 | S32: 0 | T32: 0 | U32: 0 | V32: 0 | W32: 0 | X32: 0 | Y32: 0 | Z32: 0 | AA32: 0 | AB32: 08/11/2024 | AC32: 08/11/2024 | AD32: WILLIAN | AE32: WILLIAN
A33: 08/11/2024 | B33: 052000 | C33: 1 | D33: 0 | E33: 1 | F33: 0 | G33: 0 | H33: 0 | I33: 0 | J33: 0 | K33: CASTERTECH | L33: 0084480 | M33: 03752201001 | N33: 1 | O33: 1 | P33: 0 | Q33: 0 | R33: 0 | S33: 0 | T33: 0 | U33: 0 | V33: 0 | W33: 0 | X33: 0 | Y33: 0 | Z33: 0 | AA33: 0 | AB33: 08/11/2024 | AC33: 08/11/2024 | AD33: WILLIAN/ALEXANDRE | AE33: WILLIAN | AF33: DIMENSIONAL ALEXANDRE / CONFERENCIA DESEMPENO E MONTAGEM DE CASTANHA WILLIAN
A34: 08/11/2024 | B34: 051967 | C34: 0 | D34: 0 | E34: 0 | F34: 0 | G34: 0 | H34: 0 | I34: 2 | J34: 0 | K34: T & M | L34: 0084621 | M34: 03762001013 | N34: 2 | O34: 2 | P34: 0 | Q34: 0 | R34: 0 | S34: 0 | T34: 0 | U34: 0 | V34: 0 | W34: 0 | X34: 0 | Y34: 0 | Z34: 0 | AA34: 0 | AB34: 08/11/2024 | AC34: 08/11/2024 | AD34: JOSE | AE34: WILLIAN
A35: 08/11/2024 | B35: 051986 | C35: 0 | D35: 0 | E35: 0 | F35: 0 | G35: 0 | H35: 0 | I35: 2 | J35: 0 | K35: COMERCIAL | L35: 0084446 | M35: 03771601002 | N35: 2 | O35: 2 | P35: 0 | Q35: 0 | R35: 0 | S35: 0 | T35: 0 | U35: 0 | V35: 0 | W35: 0 | X35: 0 | Y35: 0 | Z35: 0 | AA35: 0 | AB35: 08/11/2024 | AC35: 08/11/2024 | AD35: JOSÉ | AE35: WILLIAN | AF35: LIBERADO SEM USINAR COM TOLERÂNCIA DE CORTE
A36: 08/11/2024 | B36: 051983 | C36: 0 | D36: 0 | E36: 0 | F36: 0 | G36: 0 | H36: 0 | I36: 2 | J36: 0 | K36: COMERCIAL | L36: 0084445 | M36: 03771501001 | N36: 2 | O36: 2 | P36: 0 | Q36: 0 | R36: 0 | S36: 0 | T36: 0 | U36: 0 | V36: 0 | W36: 0 | X36: 0 | Y36: 0 | Z36: 0 | AA36: 0 | AB36: 08/11/2024 | AC36: 08/11/2024 | AD36: JOSÉ | AE36: WILLIAN | AF36: LIBERADO SEM USINAR COM TOLERÂNCIA DE CORTE
A37: 08/11/2024 | B37: 051984 | C37: 0 | D37: 0 | E37: 0 | F37: 0 | G37: 0 | H37: 0 | I37: 2 | J37: 0 | K37: COMERCIAL | L37: 0084446 | M37: 03771601001 | N37: 2 | O37: 2 | P37: 0 | Q37: 0 | R37: 0 | S37: 0 | T37: 0 | U37: 0 | V37: 0 | W37: 0 | X37: 0 | Y37: 0 | Z37: 0 | AA37: 0 | AB37: 08/11/2024 | AC37: 08/11/2024 | AD37: JOSÉ | AE37: WILLIAN | AF37: LIBERADO SEM USINAR COM TOLERÂNCIA DE CORTE
A38: 08/11/2024 | B38: 52215 | C38: 0 | D38: 0 | E38: 0 | F38: 2 | G38: 0 | H38: 0 | I38: 0 | J38: 0 | K38: RANDON | L38: 84767 | M38: 03767501001 | N38: 2 | O38: 2 | P38: 0 | Q38: 0 | R38: 0 | S38: 0 | T38: 0 | U38: 0 | V38: 0 | W38: 0 | X38: 0 | Y38: 0 | Z38: 0 | AA38: 0 | AB38: 08/11/2024 | AC38: 08/11/2024 | AD38: WILLIAN | AE38: WILLIAN | AF38: ALEXANDRE MONTOU CASTANHA E FEZ LAUDO
A39: 08/11/2024 | B39: 52131 | C39: 0 | D39: 0 | E39: 0 | F39: 1 | G39: 0 | H39: 0 | I39: 0 | J39: 0 | K39: INDUCTOHERM | L39: 84604 | M39: 03756401001 | N39: 1 | O39: 1 | P39: 0 | Q39: 0 | R39: 0 | S39: 0 | T39: 0 | U39: 0 | V39: 0 | W39: 0 | X39: 0 | Y39: 0 | Z39: 0 | AA39: 0 | AB39: 08/11/2024 | AC39: 08/11/2024 | AD39: WILLIAN | AE39: WILLIAN | AF39: ALEXANDRE MONTOU CASTANHA E FEZ LAUDO
A40: 08/11/2024 | B40: 052046 | C40: 0 | D40: 0 | E40: 0 | F40: 1 | G40: 0 | H40: 0 | I40: 0 | J40: 0 | K40: VANTEC | L40: 0084643 | M40: 03762501001 | N40: 1 | O40: 1 | P40: 0 | Q40: 0 | R40: 0 | S40: 0 | T40: 0 | U40: 0 | V40: 0 | W40: 0 | X40: 0 | Y40: 0 | Z40: 0 | AA40: 0 | AB40: 08/11/2024 | AC40: 08/11/2024 | AD40: WILLIAN | AE40: WILLIAN | AF40: JOSÉ MONTOU CASTANHA E DIMENSIONAL DESEMPENO WILLIAN
...

Sheet CONFIGURAÇÃO 
A1: CONFIGURAÇÃO DA PROGRAMAÇÃO
B2: =Lançamentos!O3 -> Aprovado | C2: =Lançamentos!P3 -> Reprovado | D2: =Lançamentos!Q3 -> Usinagem | E2: =Lançamentos!R3 -> Inspeção | F2: =Lançamentos!S3 -> Desenho | G2: =Lançamentos!T3 -> Programação CNC | H2: =Lançamentos!U3 -> Produção | I2: =Lançamentos!V3 -> Comercial | J2: =Lançamentos!W3 -> PCP | K2: =Lançamentos!Y3 -> Retrabalho | L2: =Lançamentos!AA3 -> Morta usin. | M2: =B2 -> Aprovado | N2: =C2 -> Reprovado | O2: =L2 -> Morta usin. | P2: =K2 -> Retrabalho
B3: =Lançamentos!O158 -> 303 | C3: =Lançamentos!P158 -> 13 | D3: =Lançamentos!Q158 -> 10 | E3: =Lançamentos!R158 -> 0 | F3: =Lançamentos!S158 -> 0 | G3: =Lançamentos!T158 -> 0 | H3: =Lançamentos!U158 -> 1 | I3: =Lançamentos!V158 -> 1 | J3: =Lançamentos!W158 -> 0 | K3: =Lançamentos!Y158 -> 8 | L3: =Lançamentos!AA158 -> 0 | M3: =B3 -> 303 | N3: =C3 -> 13 | O3: =L3 -> 0 | P3: =K3 -> 8
O4: 1 | P4: 2
O22: PERCENTUAIS
B23: ='PRODUTOS DE REFUGO'!#REF! -> #REF! | C23: ='PRODUTOS DE REFUGO'!#REF! -> #REF! | D23: ='PRODUTOS DE REFUGO'!#REF! -> #REF! | G23: TOTAL DE PEÇAS PRODUZIDAS NO MÊS | I23: PEÇAS REPROVADAS | L23: PEÇAS APROVADAS | O23: =F32 -> 0.96190476
B24: ='PRODUTOS DE REFUGO'!#REF! -> #REF! | C24: ='PRODUTOS DE REFUGO'!#REF! -> #REF! | D24: ='PRODUTOS DE REFUGO'!#REF! -> #REF! | G24: =Lançamentos!N158 -> 315 | L24: PEÇAS MORTAS | O24: =F41 -> 0
L25: PEÇAS RETRABALHO | O25: =F36 -> 0.025396825
L26: PEÇA APROV. DIR. + RETRAB. | O26: =F44 -> 0.98730159
F31: APROVAÇÃO DIRETA
F32: =M3/Lançamentos!N158 -> 0.96190476
F35: RETRABALHO
F36: =K3/Lançamentos!N158 -> 0.025396825
F40: MORTAS
F41: =L3/Lançamentos!N158 -> 0
F43: APROVAÇÃO DIRETA + RETRABALHO
F44: =SUM(F36+F32) -> 0.98730159

Sheet PRODUTOS DE REFUGO
A1: LOGO | C1: CONTROLE DE REFUGOS
A2: Data | B2: Descrição | C2: Cliente | D2: Pedido | E2: OP | F2: Maquina | G2: Fuso | H2: Castanha | I2: Guia | J2: Bloco | K2: QTD. DA OP. | L2: QTD. PEÇAS CHEGOU | M2: QNT. REPROVADO | N2: QNT. RETRABALHADO | O2: QNT. USINADO NOVAMENTE | P2: APROVADO | Q2: Usinagem | R2: Inspeção | S2: Desenho | T2: Programação CNC | U2: Produção | V2: Gerar op - instrução para corte errado | W2: PCP | X2: Medida não conforme o projeto | Y2: Usinagem não conforme o projeto | Z2: Acabamento Ruim | AA2: Peça fora de concentricidade | AB2: Peça craterizada | AC2: Estética (aparência) | AD2: Rebarba | AE2: Faltou usinar a chaveta | AF2: Desenho Errado | AG2: Observação
A3: 45601 | B3: 052114 | C3: MACCAFERRI | D3: 0084544 | E3: 03751801001 | F3: TORNO 2 | H3: X | K3: 2 | L3: 2 | M3: 1 | N3: 1 | O3: 0 | P3: 2 | Q3: X | X3: X | AG3: FLANGE MAIOR 25.6MM E PRECISO MENOR 4.4MM - OCOREU COMPENSAÇÃO DE MEDIDAS
A4: 45602 | B4: 051881 | C4: MACLINEA | D4: 0084590 | E4: 03753501001 | F4: CORTE | I4: X | K4: 3 | L4: 3 | M4: 1 | N4: 0 | O4: 1 | P4: 1 | U4: X | X4: X | AG4: CORTE ERRADO DEVIDO A TRAÇAGEM DE COTA "E" ERRADA
A5: 45602 | B5: 052102 | C5: CONAN | D5: 0084680 | E5: 03761801008 | F5: CNC | G5: X | K5: 1 | L5: 1 | M5: 1 | N5: 1 | O5: 0 | P5: 1 | Q5: X | X5: X | AG5: FUSO MORREU O CORPO DA FRENTE DE COMPRIMENTO 15mm DIAMETRO 10mm H7 E O CORPO DE 26mm DE COMPRIMENTO DIAMETRO DE 12mm h7 ESTAVA COM 50% FORA DE TOLERÂNCIA PEÇA OI LIBERADA POSSUI RNC E EMAIL.
A6: 45603 | B6: 050922 | C6: NEUMAYER | D6: 0081637 | E6: 03747601001 | F6: FRESA 2 | H6: X | K6: 1 | L6: 1 | M6: 1 | N6: 1 | O6: 0 | P6: 1 | Q6: X | Y6: X | AG6: AO REALIZAR A FURAÇÃO DO PARAFUSO DO RECIRCULADOR, O OPERADOR NÃO SE ATENTOU E PASSOU COM A FRESA ATE O FUSO
A7: 45604 | B7: 51873 | C7: ALZILAN | D7: BP#31868 | E7: - | F7: TORNO 1 | G7: X | H7: X | K7: 1 | L7: 1 | M7: 1 | N7: 1 | O7: 0 | P7: 1 | Q7: X | X7: X | Z7: X | AG7: DIAMETRO DE 24,5mm H7(0/-0,021), FICOU UMA REGIAO DE 5mm DE COMPRIMENTO COM -0,05/-0,06.
A8: 45614 | B8: 052217 | C8: HITACHI | D8: 0082111 | E8: 03766301001 | F8: TORNO 1 | G8: X | K8: 1 | L8: 1 | M8: 1 | N8: 1 | O8: 0 | P8: 1 | Q8: X | Z8: X | AG8: ACABAMENTO DA BUCHA COM CORPO DE 14,5mm DE COMPRIMENTO ESTAVA COM ACABAMENTO VIBRADO

Sheet DASH
A1: =Observações!C4 -> 2

Sheet Observações
A1: LOGO | C1: OBS
A2: Data | B2: Responsavél pela observção | C2: Assunto
C3: LANÇAR PEDIDO 0084147 DA HITACHI? POIS NÃO FOI USINADO ERA SÓ VER O DEGRAU NA CASTANHA OP 03713301001
C4: 2
C5: 3
C6: 4
C7: 5
C8: 6
C9: 7
C10: 8
C11: 9
C12: 10
C13: 11
C14: 12
C15: 13
... C17: 15

Sheet Indicadores Usinagem
B2: PLANILHA PARA ATUALIZAR QUADRO DE INFORMAÇÕES
B5: PEÇAS PRODUZIDAS MÊS ATE A PRESENTE DATA | C5: =Lançamentos!N158 -> 315
B10: APROVAÇÃO DIRETA | C10: USINAGEM
C11: =Lançamentos!O158 -> 303
B12: PERCENTUAL % | C12: USINAGEM
C13: =C11/C5 -> 0.96190476
B15: APROVAÇÃO DIRETA + RETRABALHO | C15: USINAGEM
C16: =Lançamentos!O158+Lançamentos!Y158 -> 311
B17: PERCENTUAL % | C17: USINAGEM
C18: ='CONFIGURAÇÃO '!O26 -> 0.98730159
B20: PEÇAS RETRABALHADAS | C20: USINAGEM | D20: OUTROS
C21: =C35 -> 8 | D21: =C37 -> 0
B22: PERCENTUAL % | C22: USINAGEM | D22: OUTROS
C23: =C33 -> 0.025396825 | D23: =D37 -> 0
B25: PEÇAS MORTAS | C25: USINAGEM | D25: OUTROS
C26: =C41 -> 0 | D26: =C43 -> 1
B27: PERCENTUAL % | C27: USINAGEM | D27: OUTROS
C28: =D41 -> 0 | D28: =D43 -> 0.00052910053
B31: CALCULO DIVISÃO DE NÃO CONFORMIDADE
B33: RETRABALHO | C33: ='CONFIGURAÇÃO '!O25 -> 0.025396825
D34: USINAGEM | F34: =Lançamentos!AA158 -> 0 | G34: usin morta
C35: =Lançamentos!Y158 -> 8 | D35: =C33 -> 0.025396825 | F35: =Lançamentos!Z158 -> 1 | G35: outros morta
D36: OUTROS | F36: =Lançamentos!Y158 -> 8 | G36: retrabalho usin
C37: =Lançamentos!X158 -> 0 | D37: =C33*C37 -> 0 | F37: =Lançamentos!X158 -> 0 | G37: retrabalho outros
C38: =Lançamentos!Z158/Lançamentos!N158 -> 0.0031746032
B39: PEÇA MORTA | C39: =Lançamentos!AA158/Lançamentos!N158 -> 0
D40: USINAGEM
B41: =C38/6 -> 0.00052910053 | C41: =Lançamentos!AA158 -> 0 | D41: =C41*B41 -> 0
D42: OUTROS
C43: =Lançamentos!Z158 -> 1 | D43: =B41*C43 -> 0.00052910053
